Workbook

Sheet Sheet1 (3)
A1: Patente | B1: Plan Asociado | C1: CC | D1: Fecha Plan Prox | E1: Taller Correspondiente
A2: AB320YQ | B2: 2MC | C2: =VLOOKUP(A2,[1]Detalle!$D$2:$CW$484,98,FALSE) -> CCU_MZA - Comp. Cerv. Unidas - MZA | D2: 46067
A3: AB320YQ | B3: 2MC | C3: =VLOOKUP(A3,[1]Detalle!$D$2:$CW$484,98,FALSE) -> CCU_MZA - Comp. Cerv. Unidas - MZA | D3: 46067
A4: AF088ED | B4: 2MC | C4: =VLOOKUP(A4,[1]Detalle!$D$2:$CW$484,98,FALSE) -> CMQ_TTE - QUILMES TTE | D4: 46290
A5: AF088ED | B5: 2MC | C5: =VLOOKUP(A5,[1]Detalle!$D$2:$CW$484,98,FALSE) -> CMQ_TTE - QUILMES TTE | D5: 46290
A6: AF338VO | B6: 2MC | C6: =VLOOKUP(A6,[1]Detalle!$D$2:$CW$484,98,FALSE) -> CMQ_TTE - QUILMES TTE | D6: 46338
A7: AF338VO | B7: 2MC | C7: =VLOOKUP(A7,[1]Detalle!$D$2:$CW$484,98,FALSE) -> CMQ_TTE - QUILMES TTE | D7: 46338
A8: AF364MN | B8: 2MC | C8: =VLOOKUP(A8,[1]Detalle!$D$2:$CW$484,98,FALSE) -> CMQ_TTE - QUILMES TTE | D8: 46387
A9: AF364MN | B9: 2MC | C9: =VLOOKUP(A9,[1]Detalle!$D$2:$CW$484,98,FALSE) -> CMQ_TTE - QUILMES TTE | D9: 46387
A10: AF877NC | B10: 2MC | C10: =VLOOKUP(A10,[1]Detalle!$D$2:$CW$484,98,FALSE) -> CENCO_MZ - Cencosud SA - Mendoza | D10: 46147
A11: AF877NC | B11: 2MC | C11: =VLOOKUP(A11,[1]Detalle!$D$2:$CW$484,98,FALSE) -> CENCO_MZ - Cencosud SA - Mendoza | D11: 46147
A12: AG390QD | B12: 2MC | C12: =VLOOKUP(A12,[1]Detalle!$D$2:$CW$484,98,FALSE) -> CCUDyAZA | D12: 46228
A13: AG390QD | B13: 2MC | C13: =VLOOKUP(A13,[1]Detalle!$D$2:$CW$484,98,FALSE) -> CCUDyAZA | D13: 46228
... A1294: OAF641 | B1294: 2ML 4 | C1294: =VLOOKUP(A1294,[1]Detalle!$D$2:$CW$484,98,FALSE) -> Expreso - Servicios Troncales | D1294: 46179.704

Sheet Hoja2
A3: Etiquetas de fila | B3: Suma de Valor Total
A4: ADA_CH - Danone Arg. S.A. - Chascomus | B4: 4726636.4
A5: AGN_TTE - AGUANORT - Transporte | B5: 142474.88
A6: Alfavinil | B6: 135171.2
A7: Arcor S.A.I.C. | B7: 1763536.4
A8: CCU_MZA - Comp. Cerv. Unidas - MZA | B8: 878758.72
A9: CCUCoAZA | B9: 2426080.6
A10: CCUDyAZA | B10: 3066374.1
A11: CENCO_MZ - Cencosud SA - Mendoza | B11: 1762684.9
A12: CENCO_SJ - Cencosud SA - San Juan | B12: 266258.08
A13: CENCOMLD - Cencosud SA - Mendoza | B13: 2467028.2
A14: CIMSA_BS AS | B14: 303661.48
A15: CIMSA_MZA | B15: 133759.12
... A32: Total general | B32: 45490004

Sheet Sheet1
A1: Patente | B1: Modelo | C1: Plan Asociado | D1: Plan | E1: Tiempo Hs | F1: Descripsion | G1: Ultima Fecha Cambio | H1: Km cambio | I1: Proximo KM | J1: Recorrido | K1: Km Restante | L1: Km Actaul | M1: Días transcurridos | N1: PromedioKmdiarios | O1: DıasRestantesestimados | P1: Fecha Actual | Q1: Frecuencia | R1: Fecha Plan Prox.orig | S1: Fecha Plan Prox | T1: Mes | U1: Estado | V1: Unnamed: 18 | W1: Unnamed: 19 | X1: Código | Y1: Descripción | Z1: Cantidad | AA1: Valor | AB1: Valor Total | AC1: CC | AD1: Km_anual | AE1: Fecha Plan Prox Calculada | AF1: Nro Cambio Año
A2: AB320YQ | B2: B66 - ATEGO 2426 | C2: 2MC | D2: 2MC | E2: 0.75 | F2: Cambio De Aceite Y Filtro De Motor | G2: 45745 | H2: 24484.4 | I2: 44484.4 | J2: 12540.1 | K2: 7459.9 | L2: 37024.5 | M2: 202 | N2: 67.727481 | O2: 120.16649 | P2: 45947 | Q2: 20000 | R2: 46067.166 | S2: 46067 | T2: =TEXT(R2, "mmmm") -> febrero | U2: Activo | X2: C000313 | Y2: ACEITE 15W40 XV300 X 205LT (TAMBOR) | Z2: 16 | AA2: 3389.9 | AB2: 54238.4 | AC2: =VLOOKUP(A2,[1]Detalle!$D$2:$CW$484,98,FALSE) -> CCU_MZA - Comp. Cerv. Unidas - MZA
A3: AB320YQ | B3: B66 - ATEGO 2426 | C3: 2MC | D3: 2MC | E3: 0.75 | F3: Cambio De Aceite Y Filtro De Motor | G3: 45745 | H3: 24484.4 | I3: 44484.4 | J3: 12540.1 | K3: 7459.9 | L3: 37024.5 | M3: 202 | N3: 67.727481 | O3: 120.16649 | P3: 45947 | Q3: 20000 | R3: 46067.166 | S3: 46067 | T3: =TEXT(R3, "mmmm") -> febrero | U3: Activo | X3: C002301 | Y3: FILTRO DE ACEITE 6 CILINDROS MB 1318/1218/1215/914/712/1418/915/815 - MANN HU931/5X | Z3: 1 | AA3: 8513.28 | AB3: 8513.28 | AC3: =VLOOKUP(A3,[1]Detalle!$D$2:$CW$484,98,FALSE) -> CCU_MZA - Comp. Cerv. Unidas - MZA
A4: AF088ED | B4: 958 ATEGO 1726-42 CE | C4: 2MC | D4: 2MC | E4: 0.75 | F4: Cambio De Aceite Y Filtro De Motor | G4: 45827 | H4: 68428.5 | I4: 88428.5 | J4: 5182.2 | K4: 14817.8 | L4: 73610.7 | M4: 120 | N4: 48.244391 | O4: 343.12377 | P4: 45947 | Q4: 20000 | R4: 46290.124 | S4: 46290 | T4: =TEXT(R4, "mmmm") -> septiembre | U4: Activo | X4: C000313 | Y4: ACEITE 15W40 XV300 X 205LT (TAMBOR) | Z4: 16 | AA4: 3389.9 | AB4: 54238.4 | AC4: =VLOOKUP(A4,[1]Detalle!$D$2:$CW$484,98,FALSE) -> CMQ_TTE - QUILMES TTE
A5: AF088ED | B5: 958 ATEGO 1726-42 CE | C5: 2MC | D5: 2MC | E5: 0.75 | F5: Cambio De Aceite Y Filtro De Motor | G5: 45827 | H5: 68428.5 | I5: 88428.5 | J5: 5182.2 | K5: 14817.8 | L5: 73610.7 | M5: 120 | N5: 48.244391 | O5: 343.12377 | P5: 45947 | Q5: 20000 | R5: 46290.124 | S5: 46290 | T5: =TEXT(R5, "mmmm") -> septiembre | U5: Activo | X5: C002301 | Y5: FILTRO DE ACEITE 6 CILINDROS MB 1318/1218/1215/914/712/1418/915/815 - MANN HU931/5X | Z5: 1 | AA5: 8513.28 | AB5: 8513.28 | AC5: =VLOOKUP(A5,[1]Detalle!$D$2:$CW$484,98,FALSE) -> CMQ_TTE - QUILMES TTE
A6: AF338VO | B6: ATEGO 1419 | C6: 2MC | D6: 2MC | E6: 0.75 | F6: Cambio De Aceite Y Filtro De Motor | G6: - | N6: 51.093037 | P6: 45947 | Q6: 20000 | R6: 46338.443 | S6: 46338 | T6: =TEXT(R6, "mmmm") -> noviembre | U6: Activo | X6: C000313 | Y6: ACEITE 15W40 XV300 X 205LT (TAMBOR) | Z6: 16 | AA6: 3389.9 | AB6: 54238.4 | AC6: =VLOOKUP(A6,[1]Detalle!$D$2:$CW$484,98,FALSE) -> CMQ_TTE - QUILMES TTE
A7: AF338VO | B7: ATEGO 1419 | C7: 2MC | D7: 2MC | E7: 0.75 | F7: Cambio De Aceite Y Filtro De Motor | G7: - | N7: 51.093037 | P7: 45947 | Q7: 20000 | R7: 46338.443 | S7: 46338 | T7: =TEXT(R7, "mmmm") -> noviembre | U7: Activo | X7: C002301 | Y7: FILTRO DE ACEITE 6 CILINDROS MB 1318/1218/1215/914/712/1418/915/815 - MANN HU931/5X | Z7: 1 | AA7: 8513.28 | AB7: 8513.28 | AC7: =VLOOKUP(A7,[1]Detalle!$D$2:$CW$484,98,FALSE) -> CMQ_TTE - QUILMES TTE
A8: AF364MN | B8: ATEGO 1419 | C8: 2MC | D8: 2MC | E8: 0.75 | F8: Cambio De Aceite Y Filtro De Motor | G8: 45461 | H8: 38855.1 | I8: 58855.1 | J8: 22989.9 | K8: -2989.9 | L8: 61845 | M8: 486 | N8: 45.422519 | O8: -63.205642 | P8: 45947 | Q8: 20000 | R8: 46387.31 | S8: 46387 | T8: =TEXT(R8, "mmmm") -> diciembre | U8: Activo | X8: C000313 | Y8: ACEITE 15W40 XV300 X 205LT (TAMBOR) | Z8: 16 | AA8: 3389.9 | AB8: 54238.4 | AC8: =VLOOKUP(A8,[1]Detalle!$D$2:$CW$484,98,FALSE) -> CMQ_TTE - QUILMES TTE
A9: AF364MN | B9: ATEGO 1419 | C9: 2MC | D9: 2MC | E9: 0.75 | F9: Cambio De Aceite Y Filtro De Motor | G9: 45461 | H9: 38855.1 | I9: 58855.1 | J9: 22989.9 | K9: -2989.9 | L9: 61845 | M9: 486 | N9: 45.422519 | O9: -63.205642 | P9: 45947 | Q9: 20000 | R9: 46387.31 | S9: 46387 | T9: =TEXT(R9, "mmmm") -> diciembre | U9: Activo | X9: C002301 | Y9: FILTRO DE ACEITE 6 CILINDROS MB 1318/1218/1215/914/712/1418/915/815 - MANN HU931/5X | Z9: 1 | AA9: 8513.28 | AB9: 8513.28 | AC9: =VLOOKUP(A9,[1]Detalle!$D$2:$CW$484,98,FALSE) -> CMQ_TTE - QUILMES TTE
A10: AF877NC | B10: ATEGO 1419 48 | C10: 2MC | D10: 2MC | E10: 0.75 | F10: Cambio De Aceite Y Filtro De Motor | G10: 45822 | H10: 71797 | I10: 91797 | J10: 0 | K10: 20000 | L10: 71797 | M10: 125 | N10: 4.7505769 | O10: 200 | P10: 45947 | Q10: 20000 | R10: 46147 | S10: 46147 | T10: =TEXT(R10, "mmmm") -> mayo | U10: Activo | X10: C000313 | Y10: ACEITE 15W40 XV300 X 205LT (TAMBOR) | Z10: 16 | AA10: 3389.9 | AB10: 54238.4 | AC10: =VLOOKUP(A10,[1]Detalle!$D$2:$CW$484,98,FALSE) -> CENCO_MZ - Cencosud SA - Mendoza
A11: AF877NC | B11: ATEGO 1419 48 | C11: 2MC | D11: 2MC | E11: 0.75 | F11: Cambio De Aceite Y Filtro De Motor | G11: 45822 | H11: 71797 | I11: 91797 | J11: 0 | K11: 20000 | L11: 71797 | M11: 125 | N11: 4.7505769 | O11: 200 | P11: 45947 | Q11: 20000 | R11: 46147 | S11: 46147 | T11: =TEXT(R11, "mmmm") -> mayo | U11: Activo | X11: C002301 | Y11: FILTRO DE ACEITE 6 CILINDROS MB 1318/1218/1215/914/712/1418/915/815 - MANN HU931/5X | Z11: 1 | AA11: 8513.28 | AB11: 8513.28 | AC11: =VLOOKUP(A11,[1]Detalle!$D$2:$CW$484,98,FALSE) -> CENCO_MZ - Cencosud SA - Mendoza
A12: AG390QD | B12: ACCELO 1016 39 | C12: 2MC | D12: 2MC | E12: 0.75 | F12: Cambio De Aceite Y Filtro De Motor | G12: 45727 | H12: 15836.3 | I12: 35836.3 | J12: 8775.7 | K12: 11224.3 | L12: 24612 | M12: 220 | N12: 36.572848 | O12: 281.3845 | P12: 45947 | Q12: 20000 | R12: 46228.385 | S12: 46228 | T12: =TEXT(R12, "mmmm") -> julio | U12: Activo | X12: C000313 | Y12: ACEITE 15W40 XV300 X 205LT (TAMBOR) | Z12: 16 | AA12: 3389.9 | AB12: 54238.4 | AC12: =VLOOKUP(A12,[1]Detalle!$D$2:$CW$484,98,FALSE) -> CCUDyAZA
A13: AG390QD | B13: ACCELO 1016 39 | C13: 2MC | D13: 2MC | E13: 0.75 | F13: Cambio De Aceite Y Filtro De Motor | G13: 45727 | H13: 15836.3 | I13: 35836.3 | J13: 8775.7 | K13: 11224.3 | L13: 24612 | M13: 220 | N13: 36.572848 | O13: 281.3845 | P13: 45947 | Q13: 20000 | R13: 46228.385 | S13: 46228 | T13: =TEXT(R13, "mmmm") -> julio | U13: Activo | X13: C002301 | Y13: FILTRO DE ACEITE 6 CILINDROS MB 1318/1218/1215/914/712/1418/915/815 - MANN HU931/5X | Z13: 1 | AA13: 8513.28 | AB13: 8513.28 | AC13: =VLOOKUP(A13,[1]Detalle!$D$2:$CW$484,98,FALSE) -> CCUDyAZA
A14: AG404LX | B14: ACCELO 1016 39 | C14: 2MC | D14: 2MC | E14: 0.75 | F14: Cambio De Aceite Y Filtro De Motor | G14: 45728 | H14: 16579.5 | I14: 36579.5 | J14: 8515.2 | K14: 11484.8 | L14: 25094.7 | M14: 219 | N14: 35.248013 | O14: 295.3743 | P14: 45947 | Q14: 20000 | R14: 46242.374 | S14: 46242 | T14: =TEXT(R14, "mmmm") -> agosto | U14: Activo | X14: C000313 | Y14: ACEITE 15W40 XV300 X 205LT (TAMBOR) | Z14: 16 | AA14: 3389.9 | AB14: 54238.4 | AC14: =VLOOKUP(A14,[1]Detalle!$D$2:$CW$484,98,FALSE) -> CCUDyAZA
A15: AG404LX | B15: ACCELO 1016 39 | C15: 2MC | D15: 2MC | E15: 0.75 | F15: Cambio De Aceite Y Filtro De Motor | G15: 45728 | H15: 16579.5 | I15: 36579.5 | J15: 8515.2 | K15: 11484.8 | L15: 25094.7 | M15: 219 | N15: 35.248013 | O15: 295.3743 | P15: 45947 | Q15: 20000 | R15: 46242.374 | S15: 46242 | T15: =TEXT(R15, "mmmm") -> agosto | U15: Activo | X15: C002301 | Y15: FILTRO DE ACEITE 6 CILINDROS MB 1318/1218/1215/914/712/1418/915/815 - MANN HU931/5X | Z15: 1 | AA15: 8513.28 | AB15: 8513.28 | AC15: =VLOOKUP(A15,[1]Detalle!$D$2:$CW$484,98,FALSE) -> CCUDyAZA
A16: BVH267 | B16: 914 | C16: 2MC | D16: 2MC | E16: 0.75 | F16: Cambio De Aceite Y Filtro De Motor | G16: 45530 | H16: 297464 | I16: 317464 | J16: 23030.17 | K16: -3030.17 | L16: 320494.17 | M16: 417 | N16: 48.15737 | O16: -54.866329 | P16: 45947 | Q16: 20000 | R16: 46362.305 | S16: 46362 | T16: =TEXT(R16, "mmmm") -> diciembre | U16: Activo | X16: C000313 | Y16: ACEITE 15W40 XV300 X 205LT (TAMBOR) | Z16: 16 | AA16: 3389.9 | AB16: 54238.4 | AC16: =VLOOKUP(A16,[1]Detalle!$D$2:$CW$484,98,FALSE) -> Unilever - Unilever de Arg. S.A.
A17: BVH267 | B17: 914 | C17: 2MC | D17: 2MC | E17: 0.75 | F17: Cambio De Aceite Y Filtro De Motor | G17: 45530 | H17: 297464 | I17: 317464 | J17: 23030.17 | K17: -3030.17 | L17: 320494.17 | M17: 417 | N17: 48.15737 | O17: -54.866329 | P17: 45947 | Q17: 20000 | R17: 46362.305 | S17: 46362 | T17: =TEXT(R17, "mmmm") -> diciembre | U17: Activo | X17: C002301 | Y17: FILTRO DE ACEITE 6 CILINDROS MB 1318/1218/1215/914/712/1418/915/815 - MANN HU931/5X | Z17: 1 | AA17: 8513.28 | AB17: 8513.28 | AC17: =VLOOKUP(A17,[1]Detalle!$D$2:$CW$484,98,FALSE) -> Unilever - Unilever de Arg. S.A.
A18: CVF923 | B18: 712 | C18: 2MC | D18: 2MC | E18: 0.75 | F18: Cambio De Aceite Y Filtro De Motor | G18: 45798 | H18: 32992.1 | I18: 52992.1 | J18: 9749.3 | K18: 10250.7 | L18: 42741.4 | M18: 149 | N18: 52.850396 | O18: 156.66297 | P18: 45947 | Q18: 20000 | R18: 46103.663 | S18: 46103 | T18: =TEXT(R18, "mmmm") -> marzo | U18: Activo | X18: C000313 | Y18: ACEITE 15W40 XV300 X 205LT (TAMBOR) | Z18: 16 | AA18: 3389.9 | AB18: 54238.4 | AC18: =VLOOKUP(A18,[1]Detalle!$D$2:$CW$484,98,FALSE) -> JOHNSON - SC JOHNSON DE ARGENTINA SAIC
A19: CVF923 | B19: 712 | C19: 2MC | D19: 2MC | E19: 0.75 | F19: Cambio De Aceite Y Filtro De Motor | G19: 45798 | H19: 32992.1 | I19: 52992.1 | J19: 9749.3 | K19: 10250.7 | L19: 42741.4 | M19: 149 | N19: 52.850396 | O19: 156.66297 | P19: 45947 | Q19: 20000 | R19: 46103.663 | S19: 46103 | T19: =TEXT(R19, "mmmm") -> marzo | U19: Activo | X19: C002301 | Y19: FILTRO DE ACEITE 6 CILINDROS MB 1318/1218/1215/914/712/1418/915/815 - MANN HU931/5X | Z19: 1 | AA19: 8513.28 | AB19: 8513.28 | AC19: =VLOOKUP(A19,[1]Detalle!$D$2:$CW$484,98,FALSE) -> JOHNSON - SC JOHNSON DE ARGENTINA SAIC
A20: DLW395 | B20: 1215 | C20: 2MC | D20: 2MC | E20: 0.75 | F20: Cambio De Aceite Y Filtro De Motor | G20: 45841 | H20: 16065.4 | I20: 36065.4 | J20: 5233.4 | K20: 14766.6 | L20: 21298.8 | M20: 106 | N20: 61.480495 | O20: 299.09038 | P20: 45947 | Q20: 20000 | R20: 46246.09 | S20: 46246 | T20: =TEXT(R20, "mmmm") -> agosto | U20: Activo | X20: C000313 | Y20: ACEITE 15W40 XV300 X 205LT (TAMBOR) | Z20: 16 | AA20: 3389.9 | AB20: 54238.4 | AC20: =VLOOKUP(A20,[1]Detalle!$D$2:$CW$484,98,FALSE) -> JOHNSON - SC JOHNSON DE ARGENTINA SAIC
A21: DLW395 | B21: 1215 | C21: 2MC | D21: 2MC | E21: 0.75 | F21: Cambio De Aceite Y Filtro De Motor | G21: 45841 | H21: 16065.4 | I21: 36065.4 | J21: 5233.4 | K21: 14766.6 | L21: 21298.8 | M21: 106 | N21: 61.480495 | O21: 299.09038 | P21: 45947 | Q21: 20000 | R21: 46246.09 | S21: 46246 | T21: =TEXT(R21, "mmmm") -> agosto | U21: Activo | X21: C002301 | Y21: FILTRO DE ACEITE 6 CILINDROS MB 1318/1218/1215/914/712/1418/915/815 - MANN HU931/5X | Z21: 1 | AA21: 8513.28 | AB21: 8513.28 | AC21: =VLOOKUP(A21,[1]Detalle!$D$2:$CW$484,98,FALSE) -> JOHNSON - SC JOHNSON DE ARGENTINA SAIC
A22: FCD324 | B22: 710 | C22: 2MC | D22: 2MC | E22: 0.75 | F22: Cambio De Aceite Y Filtro De Motor | G22: 45632 | H22: 16040 | I22: 36040 | J22: 34694.1 | K22: -14694.1 | L22: 50734.1 | M22: 315 | N22: 104.47372 | O22: -133.41293 | P22: 45947 | Q22: 20000 | R22: 46138.436 | S22: 46138 | T22: =TEXT(R22, "mmmm") -> abril | U22: Activo | X22: C000313 | Y22: ACEITE 15W40 XV300 X 205LT (TAMBOR) | Z22: 16 | AA22: 3389.9 | AB22: 54238.4 | AC22: =VLOOKUP(A22,[1]Detalle!$D$2:$CW$484,98,FALSE) -> SUC_MEN - Sucursal Mendoza
A23: FCD324 | B23: 710 | C23: 2MC | D23: 2MC | E23: 0.75 | F23: Cambio De Aceite Y Filtro De Motor | G23: 45632 | H23: 16040 | I23: 36040 | J23: 34694.1 | K23: -14694.1 | L23: 50734.1 | M23: 315 | N23: 104.47372 | O23: -133.41293 | P23: 45947 | Q23: 20000 | R23: 46138.436 | S23: 46138 | T23: =TEXT(R23, "mmmm") -> abril | U23: Activo | X23: C002301 | Y23: FILTRO DE ACEITE 6 CILINDROS MB 1318/1218/1215/914/712/1418/915/815 - MANN HU931/5X | Z23: 1 | AA23: 8513.28 | AB23: 8513.28 | AC23: =VLOOKUP(A23,[1]Detalle!$D$2:$CW$484,98,FALSE) -> SUC_MEN - Sucursal Mendoza
A24: FGV321 | B24: 1218 | C24: 2MC | D24: 2MC | E24: 0.75 | F24: Cambio De Aceite Y Filtro De Motor | G24: 45769 | H24: 302541 | I24: 322541 | J24: 8078.8 | K24: 11921.2 | L24: 310619.8 | M24: 178 | N24: 40.451194 | O24: 262.6595 | P24: 45947 | Q24: 20000 | R24: 46209.66 | S24: 46209 | T24: =TEXT(R24, "mmmm") -> julio | U24: Activo | X24: C000313 | Y24: ACEITE 15W40 XV300 X 205LT (TAMBOR) | Z24: 16 | AA24: 3389.9 | AB24: 54238.4 | AC24: =VLOOKUP(A24,[1]Detalle!$D$2:$CW$484,98,FALSE) -> CCUCoAZA
A25: FGV321 | B25: 1218 | C25: 2MC | D25: 2MC | E25: 0.75 | F25: Cambio De Aceite Y Filtro De Motor | G25: 45769 | H25: 302541 | I25: 322541 | J25: 8078.8 | K25: 11921.2 | L25: 310619.8 | M25: 178 | N25: 40.451194 | O25: 262.6595 | P25: 45947 | Q25: 20000 | R25: 46209.66 | S25: 46209 | T25: =TEXT(R25, "mmmm") -> julio | U25: Activo | X25: C002301 | Y25: FILTRO DE ACEITE 6 CILINDROS MB 1318/1218/1215/914/712/1418/915/815 - MANN HU931/5X | Z25: 1 | AA25: 8513.28 | AB25: 8513.28 | AC25: =VLOOKUP(A25,[1]Detalle!$D$2:$CW$484,98,FALSE) -> CCUCoAZA
A26: FJT707 | B26: 1218 | C26: 2MC | D26: 2MC | E26: 0.75 | F26: Cambio De Aceite Y Filtro De Motor | G26: 45617 | H26: 17571.7 | I26: 37571.7 | J26: 31178.54 | K26: -11178.54 | L26: 48750.24 | M26: 330 | N26: 86.918457 | O26: -118.31594 | P26: 45947 | Q26: 20000 | R26: 46177.101 | S26: 46177 | T26: =TEXT(R26, "mmmm") -> junio | U26: Activo | X26: C000313 | Y26: ACEITE 15W40 XV300 X 205LT (TAMBOR) | Z26: 16 | AA26: 3389.9 | AB26: 54238.4 | AC26: =VLOOKUP(A26,[1]Detalle!$D$2:$CW$484,98,FALSE) -> SUC_MEN - Sucursal Mendoza
A27: FJT707 | B27: 1218 | C27: 2MC | D27: 2MC | E27: 0.75 | F27: Cambio De Aceite Y Filtro De Motor | G27: 45617 | H27: 17571.7 | I27: 37571.7 | J27: 31178.54 | K27: -11178.54 | L27: 48750.24 | M27: 330 | N27: 86.918457 | O27: -118.31594 | P27: 45947 | Q27: 20000 | R27: 46177.101 | S27: 46177 | T27: =TEXT(R27, "mmmm") -> junio | U27: Activo | X27: C002301 | Y27: FILTRO DE ACEITE 6 CILINDROS MB 1318/1218/1215/914/712/1418/915/815 - MANN HU931/5X | Z27: 1 | AA27: 8513.28 | AB27: 8513.28 | AC27: =VLOOKUP(A27,[1]Detalle!$D$2:$CW$484,98,FALSE) -> SUC_MEN - Sucursal Mendoza
... A29: GYB034 | B29: 710 | C29: 2MC | D29: 2MC | E29: 0.75 | F29: Cambio De Aceite Y Filtro De Motor | G29: 45378 | H29: 202420 | I29: 222420 | J29: 36588.56 | K29: -16588.56 | L29: 239008.56 | M29: 569 | N29: 69.022379 | O29: -257.97382 | P29: 45947 | Q29: 20000 | R29: 46236.761 | S29: 46236 | T29: =TEXT(R29, "mmmm") -> agosto | U29: Activo | X29: C002301 | Y29: FILTRO DE ACEITE 6 CILINDROS MB 1318/1218/1215/914/712/1418/915/815 - MANN HU931/5X | Z29: 1 | AA29: 8513.28 | AB29: 8513.28 | AC29: =VLOOKUP(A29,[1]Detalle!$D$2:$CW$484,98,FALSE) -> SUC_MEN - Sucursal Mendoza
A30: IVD940 | B30: ATEGO 1418/48 FRONTAL | C30: 2MC | D30: 2MC | E30: 0.75 | F30: Cambio De Aceite Y Filtro De Motor | G30: 45742 | H30: 283696 | I30: 303696 | J30: 7346 | K30: 12654 | L30: 291042 | M30: 205 | N30: 34.247774 | O30: 353.12687 | P30: 45947 | Q30: 20000 | R30: 46300.127 | S30: 46300 | T30: =TEXT(R30, "mmmm") -> octubre | U30: Activo | X30: C000313 | Y30: ACEITE 15W40 XV300 X 205LT (TAMBOR) | Z30: 16 | AA30: 3389.9 | AB30: 54238.4 | AC30: =VLOOKUP(A30,[1]Detalle!$D$2:$CW$484,98,FALSE) -> CCUCoAZA
A31: IVD940 | B31: ATEGO 1418/48 FRONTAL | C31: 2MC | D31: 2MC | E31: 0.75 | F31: Cambio De Aceite Y Filtro De Motor | G31: 45742 | H31: 283696 | I31: 303696 | J31: 7346 | K31: 12654 | L31: 291042 | M31: 205 | N31: 34.247774 | O31: 353.12687 | P31: 45947 | Q31: 20000 | R31: 46300.127 | S31: 46300 | T31: =TEXT(R31, "mmmm") -> octubre | U31: Activo | X31: C002301 | Y31: FILTRO DE ACEITE 6 CILINDROS MB 1318/1218/1215/914/712/1418/915/815 - MANN HU931/5X | Z31: 1 | AA31: 8513.28 | AB31: 8513.28 | AC31: =VLOOKUP(A31,[1]Detalle!$D$2:$CW$484,98,FALSE) -> CCUCoAZA
A32: IVD941 | B32: ATEGO 1418/48 FRONTAL | C32: 2MC | D32: 2MC | E32: 0.75 | F32: Cambio De Aceite Y Filtro De Motor | G32: 45842 | H32: 227732 | I32: 247732 | J32: 5333.9 | K32: 14666.1 | L32: 233065.9 | M32: 105 | N32: 40.479774 | O32: 288.70817 | P32: 45947 | Q32: 20000 | R32: 46235.708 | S32: 46235 | T32: =TEXT(R32, "mmmm") -> agosto | U32: Activo | X32: C000313 | Y32: ACEITE 15W40 XV300 X 205LT (TAMBOR) | Z32: 16 | AA32: 3389.9 | AB32: 54238.4 | AC32: =VLOOKUP(A32,[1]Detalle!$D$2:$CW$484,98,FALSE) -> CCUCoAZA
A33: IVD941 | B33: ATEGO 1418/48 FRONTAL | C33: 2MC | D33: 2MC | E33: 0.75 | F33: Cambio De Aceite Y Filtro De Motor | G33: 45842 | H33: 227732 | I33: 247732 | J33: 5333.9 | K33: 14666.1 | L33: 233065.9 | M33: 105 | N33: 40.479774 | O33: 288.70817 | P33: 45947 | Q33: 20000 | R33: 46235.708 | S33: 46235 | T33: =TEXT(R33, "mmmm") -> agosto | U33: Activo | X33: C002301 | Y33: FILTRO DE ACEITE 6 CILINDROS MB 1318/1218/1215/914/712/1418/915/815 - MANN HU931/5X | Z33: 1 | AA33: 8513.28 | AB33: 8513.28 | AC33: =VLOOKUP(A33,[1]Detalle!$D$2:$CW$484,98,FALSE) -> CCUCoAZA
A34: JKQ773 | B34: ATEGO 1418/48 FRONTAL | C34: 2MC | D34: 2MC | E34: 0.75 | F34: Cambio De Aceite Y Filtro De Motor | G34: 45790 | H34: 237476 | I34: 257476 | J34: 6287.2 | K34: 13712.8 | L34: 243763.2 | M34: 157 | N34: 36.853916 | O34: 342.42741 | P34: 45947 | Q34: 20000 | R34: 46289.427 | S34: 46289 | T34: =TEXT(R34, "mmmm") -> septiembre | U34: Activo | X34: C000313 | Y34: ACEITE 15W40 XV300 X 205LT (TAMBOR) | Z34: 15 | AA34: 3389.9 | AB34: =AA34*Z34 -> 50848.5 | AC34: =VLOOKUP(A34,[1]Detalle!$D$2:$CW$484,98,FALSE) -> CCUDyAZA
A35: JKQ773 | B35: ATEGO 1418/48 FRONTAL | C35: 2MC | D35: 2MC | E35: 0.75 | F35: Cambio De Aceite Y Filtro De Motor | G35: 45790 | H35: 237476 | I35: 257476 | J35: 6287.2 | K35: 13712.8 | L35: 243763.2 | M35: 157 | N35: 36.853916 | O35: 342.42741 | P35: 45947 | Q35: 20000 | R35: 46289.427 | S35: 46289 | T35: =TEXT(R35, "mmmm") -> septiembre | U35: Activo | X35: C002301 | Y35: FILTRO DE ACEITE 6 CILINDROS MB 1318/1218/1215/914/712/1418/915/815 - MANN HU931/5X | Z35: 1 | AA35: 8513.28 | AB35: 8513.28 | AC35: =VLOOKUP(A35,[1]Detalle!$D$2:$CW$484,98,FALSE) -> CCUDyAZA
A36: JKQ774 | B36: ATEGO 1418/48 FRONTAL | C36: 2MC | D36: 2MC | E36: 0.75 | F36: Cambio De Aceite Y Filtro De Motor | G36: 45785 | H36: 249976 | I36: 269976 | J36: 7170.1 | K36: 12829.9 | L36: 257146.1 | M36: 162 | N36: 37.516849 | O36: 289.87654 | P36: 45947 | Q36: 20000 | R36: 46236.877 | S36: 46236 | T36: =TEXT(R36, "mmmm") -> agosto | U36: Activo | X36: C000313 | Y36: ACEITE 15W40 XV300 X 205LT (TAMBOR) | Z36: 16 | AA36: 3389.9 | AB36: 54238.4 | AC36: =VLOOKUP(A36,[1]Detalle!$D$2:$CW$484,98,FALSE) -> CCUCoAZA
A37: JKQ774 | B37: ATEGO 1418/48 FRONTAL | C37: 2MC | D37: 2MC | E37: 0.75 | F37: Cambio De Aceite Y Filtro De Motor | G37: 45785 | H37: 249976 | I37: 269976 | J37: 7170.1 | K37: 12829.9 | L37: 257146.1 | M37: 162 | N37: 37.516849 | O37: 289.87654 | P37: 45947 | Q37: 20000 | R37: 46236.877 | S37: 46236 | T37: =TEXT(R37, "mmmm") -> agosto | U37: Activo | X37: C002301 | Y37: FILTRO DE ACEITE 6 CILINDROS MB 1318/1218/1215/914/712/1418/915/815 - MANN HU931/5X | Z37: 1 | AA37: 8513.28 | AB37: 8513.28 | AC37: =VLOOKUP(A37,[1]Detalle!$D$2:$CW$484,98,FALSE) -> CCUCoAZA
A38: JXZ992 | B38: ATEGO 1418/48 FRONTAL | C38: 2MC | D38: 2MC | E38: 0.75 | F38: Cambio De Aceite Y Filtro De Motor | G38: 45656 | H38: 216285 | I38: 236285 | J38: 9057.09 | K38: 10942.91 | L38: 225342.09 | M38: 291 | N38: 33.420996 | O38: 351.5905 | P38: 45947 | Q38: 20000 | R38: 46298.591 | S38: 46298 | T38: =TEXT(R38, "mmmm") -> octubre | U38: Activo | X38: C000313 | Y38: ACEITE 15W40 XV300 X 205LT (TAMBOR) | Z38: 16 | AA38: 3389.9 | AB38: 54238.4 | AC38: =VLOOKUP(A38,[1]Detalle!$D$2:$CW$484,98,FALSE) -> CCUCoAZA
A39: JXZ992 | B39: ATEGO 1418/48 FRONTAL | C39: 2MC | D39: 2MC | E39: 0.75 | F39: Cambio De Aceite Y Filtro De Motor | G39: 45656 | H39: 216285 | I39: 236285 | J39: 9057.09 | K39: 10942.91 | L39: 225342.09 | M39: 291 | N39: 33.420996 | O39: 351.5905 | P39: 45947 | Q39: 20000 | R39: 46298.591 | S39: 46298 | T39: =TEXT(R39, "mmmm") -> octubre | U39: Activo | X39: C002301 | Y39: FILTRO DE ACEITE 6 CILINDROS MB 1318/1218/1215/914/712/1418/915/815 - MANN HU931/5X | Z39: 1 | AA39: 8513.28 | AB39: 8513.28 | AC39: =VLOOKUP(A39,[1]Detalle!$D$2:$CW$484,98,FALSE) -> CCUCoAZA
A40: KHS009 | B40: ATRON 1720/48 FRONTAL | C40: 2MC | D40: 2MC | E40: 0.75 | F40: Cambio De Aceite Y Filtro De Motor | G40: 45525 | H40: 880145 | I40: 900145 | J40: 79750.57 | K40: -59750.57 | L40: 959895.57 | M40: 422 | N40: 249.75151 | O40: -316.17004 | P40: 45947 | Q40: 20000 | R40: 46027.08 | S40: 46027 | T40: =TEXT(R40, "mmmm") -> enero | U40: Activo | X40: C000313 | Y40: ACEITE 15W40 XV300 X 205LT (TAMBOR) | Z40: 16 | AA40: 3389.9 | AB40: 54238.4 | AC40: =VLOOKUP(A40,[1]Detalle!$D$2:$CW$484,98,FALSE) -> CENCO_MZ - Cencosud SA - Mendoza
A41: KHS009 | B41: ATRON 1720/48 FRONTAL | C41: 2MC | D41: 2MC | E41: 0.75 | F41: Cambio De Aceite Y Filtro De Motor | G41: 45525 | H41: 880145 | I41: 900145 | J41: 79750.57 | K41: -59750.57 | L41: 959895.57 | M41: 422 | N41: 249.75151 | O41: -316.17004 | P41: 45947 | Q41: 20000 | R41: 46027.08 | S41: 46027 | T41: =TEXT(R41, "mmmm") -> enero | U41: Activo | X41: C002301 | Y41: FILTRO DE ACEITE 6 CILINDROS MB 1318/1218/1215/914/712/1418/915/815 - MANN HU931/5X | Z41: 1 | AA41: 8513.28 | AB41: 8513.28 | AC41: =VLOOKUP(A41,[1]Detalle!$D$2:$CW$484,98,FALSE) -> CENCO_MZ - Cencosud SA - Mendoza
...

Sheet Hoja11
A1: ADA_CH - Danone Arg. S.A. - Chascomus
A2: AGN_TTE - AGUANORT - Transporte
A3: Alfavini - Alfavinil
A4: Arcor - Arcor
A5: CCU_MZA - Compañía Industrial Cervecera
A6: CCUCoAZA - Compañía Industrial Cer Alianz
A7: CCUDyAZA - Compañía Industrial Cer Alianz
A8: CENCO_MZ - Cencosud SA - Mendoza
A9: CENCO_SJ - Cencosud SA - San Juan
A10: CENCOMLD - Cencosud MZA Larga Distancia
A11: CIMSA_BS AS
A12: CIMSA_SRA
... A27: Unilever - Unilever de Arg. S.A.

Sheet Hoja1
B1: ene | C1: feb | D1: mar | E1: abr | F1: may | G1: jun | H1: jul | I1: ago | J1: sep | K1: oct | L1: nov | M1: dic | N1: Total general
A2: Etiquetas de fila
A3: ADA_CH - Danone Arg. S.A. - Chascomus | B3: 1411247.5 | C3: 490552.56 | D3: 369732.1 | E3: 735828.84 | F3: 1043856.8 | H3: 245276.28 | I3: 430142.33 | N3: 4726636.4
A4: AGN_TTE - AGUANORT - Transporte | L4: 142474.88 | N4: 142474.88
A5: CENCO_MZ - Cencosud SA - Mendoza | B5: 399065.12 | D5: 129862.88 | F5: 767580.58 | G5: 125503.36 | H5: 129862.88 | J5: 143698.88 | K5: 67111.2 | N5: 1762684.9
A6: CENCO_SJ - Cencosud SA - San Juan | C6: 136395.2 | E6: 62751.68 | I6: 67111.2 | N6: 266258.08
A7: CIMSA_BS AS | C7: 125015.94 | I7: 133903.95 | L7: 44741.59 | N7: 303661.48
A8: CIMSA_SRA | G8: 15918.62 | H8: 28822.97 | N8: 44741.59
A9: CMQ_TTE - QUILMES TTE | C9: 284638.6 | D9: 521516.9 | E9: 467082.02 | F9: 476271.52 | G9: 582041.13 | H9: 696546 | I9: 416987.04 | J9: 1249616.4 | K9: 1068843.6 | L9: 2094632.5 | M9: 1022668.4 | N9: 8880844.1
A10: Expreso - Servicios Troncales | B10: 2627468.2 | C10: 743178.48 | D10: 966052.43 | E10: 444802.2 | F10: 615008.38 | G10: 650674.83 | H10: 252625.92 | I10: 437491.97 | J10: 111434.28 | N10: 6848736.7
A11: JOHNSON - SC JOHNSON DE ARGENTINA SAIC | D11: 451124.13 | I11: 396120.96 | N11: 847245.09
A12: Papelera - Papelera del Plata S.A. | C12: 136395.2 | D12: 309956.32 | E12: 136395.2 | F12: 92696.96 | G12: 189479.04 | H12: 134222.4 | I12: 129862.88 | J12: 388625.92 | K12: 259459.84 | L12: 67111.2 | N12: 1844205
A13: Sin Operación | B13: 301197.21 | C13: 586108.48 | D13: 301577.28 | E13: 173204.32 | F13: 178512.64 | G13: 125503.36 | H13: 115760.96 | J13: 188180.48 | M13: 110452.64 | N13: 2080497.4
A14: SUC_CTC - Sucursal Buenos Aires | B14: 66997.85 | C14: 72419.52 | D14: 121902.81 | G14: 62751.68 | H14: 244421.83 | K14: 11957.23 | L14: 41191.41 | N14: 621642.33
A15: SUC_GAL - Sucursal General Alvear | G15: 125503.36 | N15: 125503.36
A16: SUC_MAL - Sucursal Malargüe | B16: 62751.68 | N16: 62751.68
A17: SUC_MEN - Sucursal Mendoza | B17: 18045.55 | C17: 225760.07 | D17: 136395.2 | E17: 129862.88 | F17: 18045.55 | G17: 219843.96 | H17: 244421.83 | I17: 266258.08 | K17: 53148.64 | L17: 129862.88 | N17: 1441644.6
A18: SUC_REA - Sucursal Realicó | C18: 62751.68 | D18: 37165.92 | E18: 67111.2 | H18: 125503.36 | J18: 104277.12 | M18: 110452.64 | N18: 507261.92
A19: SUC_ROS - Sucursal Rosario | E19: 18045.55 | F19: 103857.26 | I19: 18045.55 | J19: 89981.08 | N19: 229929.44
A20: SUC_SLU - Sucursal San Luis | B20: 121902.81 | H20: 136395.2 | N20: 258298.01
A21: SUC_SRA - Sucursal San Rafael | B21: 387514.22 | F21: 72419.52 | H21: 62751.68 | J21: 136395.2 | K21: 188255.04 | M21: 72419.52 | N21: 919755.18
A22: Unilever - Unilever de Arg. S.A. | B22: 97056.48 | E22: 272790.4 | F22: 136395.2 | G22: 483930.53 | H22: 121902.81 | I22: 254075.12 | J22: 413374.96 | K22: 62751.68 | M22: 266258.08 | N22: 2108535.3
A23: CIMSA_MZA | M23: 133759.12 | N23: 133759.12
A24: CCU_MZA - Compañía Industrial Cervecera | C24: 142474.88 | E24: 199146.88 | F24: 62751.68 | H24: 136395.2 | L24: 166340.48 | M24: 136395.2 | N24: 843504.32
A25: CCUDyAZA - Compañía Industrial Cer Alianz | C25: 111434.28 | D25: 251006.72 | E25: 329009.76 | F25: 251006.72 | G25: 421706.72 | H25: 229780.48 | I25: 99917.6 | J25: 865938.24 | K25: 272790.4 | L25: 123064.64 | M25: 389588.64 | N25: 3345244.2
A26: CCUCoAZA - Compañía Industrial Cer Alianz | D26: 188255.04 | E26: 129862.88 | F26: 125503.36 | G26: 67111.2 | H26: 296891.68 | I26: 535956.48 | J26: 265034.08 | K26: 551207.84 | L26: 266258.08 | N26: 2426080.6
A27: Topacio - Topacio | C27: 136395.2 | I27: 142474.88 | N27: 278870.08
A28: Arcor - Arcor | B28: 184866.05 | D28: 62751.68 | E28: 184866.05 | F28: 257285.57 | G28: 184866.05 | H28: 184866.05 | I28: 407734.61 | J28: 111434.28 | M28: 184866.05 | N28: 1763536.4
A29: Alfavini - Alfavinil | I29: 135171.2 | N29: 135171.2
A30: CENCOMLD - Cencosud MZA Larga Distancia | B30: 653586.54 | C30: 499889.77 | D30: 214811.33 | F30: 299689.32 | G30: 328564.93 | H30: 62751.68 | J30: 407734.61 | N30: 2467028.2
A31: LlaveLay | C31: 9054.85 | D31: 44093.79 | I31: 20353.94 | N31: 73502.58

Sheet Sheet1 (2)
A1: Patente | B1: Plan Asociado | C1: Plan | D1: Descripsion | E1: Ultima Fecha Cambio | F1: Km cambio | G1: Proximo KM | H1: Recorrido | I1: Km Restante | J1: Km Actaul | K1: Días transcurridos | L1: PromedioKmdiarios | M1: DıasRestantesestimados | N1: Fecha Actual | O1: Frecuencia | P1: Fecha Plan Prox | Q1: Estado | R1: Unnamed: 18 | S1: Unnamed: 19 | T1: Código | U1: Descripción | V1: Cantidad | W1: Valor | X1: Valor Total | Y1: CC
A2: AB320YQ | B2: 2MC | C2: 2MC | D2: Cambio De Aceite Y Filtro De Motor | E2: 45745 | F2: 24484.4 | G2: 44484.4 | H2: 12540.1 | I2: 7459.9 | J2: 37024.5 | K2: 202 | L2: 67.727481 | M2: 120.16649 | N2: 45947 | O2: 20000 | P2: 46067.166 | Q2: Activo | T2: C000313 | U2: ACEITE 15W40 XV300 X 205LT (TAMBOR) | V2: 16 | W2: 3389.9 | X2: 54238.4 | Y2: =VLOOKUP(A2,[1]Detalle!$D$2:$CR$484,93,FALSE) -> CCU_MZA - Comp. Cerv. Unidas - MZA
A3: AB320YQ | B3: 2MC | C3: 2MC | D3: Cambio De Aceite Y Filtro De Motor | E3: 45745 | F3: 24484.4 | G3: 44484.4 | H3: 12540.1 | I3: 7459.9 | J3: 37024.5 | K3: 202 | L3: 67.727481 | M3: 120.16649 | N3: 45947 | O3: 20000 | P3: 46067.166 | Q3: Activo | T3: C002301 | U3: FILTRO DE ACEITE 6 CILINDROS MB 1318/1218/1215/914/712/1418/915/815 - MANN HU931/5X | V3: 1 | W3: 8513.28 | X3: 8513.28 | Y3: =VLOOKUP(A3,[1]Detalle!$D$2:$CR$484,93,FALSE) -> CCU_MZA - Comp. Cerv. Unidas - MZA
A4: AF088ED | B4: 2MC | C4: 2MC | D4: Cambio De Aceite Y Filtro De Motor | E4: 45827 | F4: 68428.5 | G4: 88428.5 | H4: 5182.2 | I4: 14817.8 | J4: 73610.7 | K4: 120 | L4: 48.244391 | M4: 343.12377 | N4: 45947 | O4: 20000 | P4: 46290.124 | Q4: Activo | T4: C000313 | U4: ACEITE 15W40 XV300 X 205LT (TAMBOR) | V4: 16 | W4: 3389.9 | X4: 54238.4 | Y4: =VLOOKUP(A4,[1]Detalle!$D$2:$CR$484,93,FALSE) -> CMQ_TTE - QUILMES TTE
A5: AF088ED | B5: 2MC | C5: 2MC | D5: Cambio De Aceite Y Filtro De Motor | E5: 45827 | F5: 68428.5 | G5: 88428.5 | H5: 5182.2 | I5: 14817.8 | J5: 73610.7 | K5: 120 | L5: 48.244391 | M5: 343.12377 | N5: 45947 | O5: 20000 | P5: 46290.124 | Q5: Activo | T5: C002301 | U5: FILTRO DE ACEITE 6 CILINDROS MB 1318/1218/1215/914/712/1418/915/815 - MANN HU931/5X | V5: 1 | W5: 8513.28 | X5: 8513.28 | Y5: =VLOOKUP(A5,[1]Detalle!$D$2:$CR$484,93,FALSE) -> CMQ_TTE - QUILMES TTE
A6: AF338VO | B6: 2MC | C6: 2MC | D6: Cambio De Aceite Y Filtro De Motor | E6: - | L6: 51.093037 | N6: 45947 | O6: 20000 | P6: 46338.443 | Q6: Activo | T6: C000313 | U6: ACEITE 15W40 XV300 X 205LT (TAMBOR) | V6: 16 | W6: 3389.9 | X6: 54238.4 | Y6: =VLOOKUP(A6,[1]Detalle!$D$2:$CR$484,93,FALSE) -> CMQ_TTE - QUILMES TTE
A7: AF338VO | B7: 2MC | C7: 2MC | D7: Cambio De Aceite Y Filtro De Motor | E7: - | L7: 51.093037 | N7: 45947 | O7: 20000 | P7: 46338.443 | Q7: Activo | T7: C002301 | U7: FILTRO DE ACEITE 6 CILINDROS MB 1318/1218/1215/914/712/1418/915/815 - MANN HU931/5X | V7: 1 | W7: 8513.28 | X7: 8513.28 | Y7: =VLOOKUP(A7,[1]Detalle!$D$2:$CR$484,93,FALSE) -> CMQ_TTE - QUILMES TTE
A8: AF364MN | B8: 2MC | C8: 2MC | D8: Cambio De Aceite Y Filtro De Motor | E8: 45461 | F8: 38855.1 | G8: 58855.1 | H8: 22989.9 | I8: -2989.9 | J8: 61845 | K8: 486 | L8: 45.422519 | M8: -63.205642 | N8: 45947 | O8: 20000 | P8: 46387.31 | Q8: Activo | T8: C000313 | U8: ACEITE 15W40 XV300 X 205LT (TAMBOR) | V8: 16 | W8: 3389.9 | X8: 54238.4 | Y8: =VLOOKUP(A8,[1]Detalle!$D$2:$CR$484,93,FALSE) -> CMQ_TTE - QUILMES TTE
A9: AF364MN | B9: 2MC | C9: 2MC | D9: Cambio De Aceite Y Filtro De Motor | E9: 45461 | F9: 38855.1 | G9: 58855.1 | H9: 22989.9 | I9: -2989.9 | J9: 61845 | K9: 486 | L9: 45.422519 | M9: -63.205642 | N9: 45947 | O9: 20000 | P9: 46387.31 | Q9: Activo | T9: C002301 | U9: FILTRO DE ACEITE 6 CILINDROS MB 1318/1218/1215/914/712/1418/915/815 - MANN HU931/5X | V9: 1 | W9: 8513.28 | X9: 8513.28 | Y9: =VLOOKUP(A9,[1]Detalle!$D$2:$CR$484,93,FALSE) -> CMQ_TTE - QUILMES TTE
A10: AF877NC | B10: 2MC | C10: 2MC | D10: Cambio De Aceite Y Filtro De Motor | E10: 45822 | F10: 71797 | G10: 91797 | H10: 0 | I10: 20000 | J10: 71797 | K10: 125 | L10: 4.7505769 | M10: 200 | N10: 45947 | O10: 20000 | P10: 46147 | Q10: Activo | T10: C000313 | U10: ACEITE 15W40 XV300 X 205LT (TAMBOR) | V10: 16 | W10: 3389.9 | X10: 54238.4 | Y10: =VLOOKUP(A10,[1]Detalle!$D$2:$CR$484,93,FALSE) -> CENCO_MZ - Cencosud SA - Mendoza
A11: AF877NC | B11: 2MC | C11: 2MC | D11: Cambio De Aceite Y Filtro De Motor | E11: 45822 | F11: 71797 | G11: 91797 | H11: 0 | I11: 20000 | J11: 71797 | K11: 125 | L11: 4.7505769 | M11: 200 | N11: 45947 | O11: 20000 | P11: 46147 | Q11: Activo | T11: C002301 | U11: FILTRO DE ACEITE 6 CILINDROS MB 1318/1218/1215/914/712/1418/915/815 - MANN HU931/5X | V11: 1 | W11: 8513.28 | X11: 8513.28 | Y11: =VLOOKUP(A11,[1]Detalle!$D$2:$CR$484,93,FALSE) -> CENCO_MZ - Cencosud SA - Mendoza
A12: AG390QD | B12: 2MC | C12: 2MC | D12: Cambio De Aceite Y Filtro De Motor | E12: 45727 | F12: 15836.3 | G12: 35836.3 | H12: 8775.7 | I12: 11224.3 | J12: 24612 | K12: 220 | L12: 36.572848 | M12: 281.3845 | N12: 45947 | O12: 20000 | P12: 46228.385 | Q12: Activo | T12: C000313 | U12: ACEITE 15W40 XV300 X 205LT (TAMBOR) | V12: 16 | W12: 3389.9 | X12: 54238.4 | Y12: =VLOOKUP(A12,[1]Detalle!$D$2:$CR$484,93,FALSE) -> CCUDyAZA
A13: AG390QD | B13: 2MC | C13: 2MC | D13: Cambio De Aceite Y Filtro De Motor | E13: 45727 | F13: 15836.3 | G13: 35836.3 | H13: 8775.7 | I13: 11224.3 | J13: 24612 | K13: 220 | L13: 36.572848 | M13: 281.3845 | N13: 45947 | O13: 20000 | P13: 46228.385 | Q13: Activo | T13: C002301 | U13: FILTRO DE ACEITE 6 CILINDROS MB 1318/1218/1215/914/712/1418/915/815 - MANN HU931/5X | V13: 1 | W13: 8513.28 | X13: 8513.28 | Y13: =VLOOKUP(A13,[1]Detalle!$D$2:$CR$484,93,FALSE) -> CCUDyAZA
A14: AG404LX | B14: 2MC | C14: 2MC | D14: Cambio De Aceite Y Filtro De Motor | E14: 45728 | F14: 16579.5 | G14: 36579.5 | H14: 8515.2 | I14: 11484.8 | J14: 25094.7 | K14: 219 | L14: 35.248013 | M14: 295.3743 | N14: 45947 | O14: 20000 | P14: 46242.374 | Q14: Activo | T14: C000313 | U14: ACEITE 15W40 XV300 X 205LT (TAMBOR) | V14: 16 | W14: 3389.9 | X14: 54238.4 | Y14: =VLOOKUP(A14,[1]Detalle!$D$2:$CR$484,93,FALSE) -> CCUDyAZA
A15: AG404LX | B15: 2MC | C15: 2MC | D15: Cambio De Aceite Y Filtro De Motor | E15: 45728 | F15: 16579.5 | G15: 36579.5 | H15: 8515.2 | I15: 11484.8 | J15: 25094.7 | K15: 219 | L15: 35.248013 | M15: 295.3743 | N15: 45947 | O15: 20000 | P15: 46242.374 | Q15: Activo | T15: C002301 | U15: FILTRO DE ACEITE 6 CILINDROS MB 1318/1218/1215/914/712/1418/915/815 - MANN HU931/5X | V15: 1 | W15: 8513.28 | X15: 8513.28 | Y15: =VLOOKUP(A15,[1]Detalle!$D$2:$CR$484,93,FALSE) -> CCUDyAZA
A16: BVH267 | B16: 2MC | C16: 2MC | D16: Cambio De Aceite Y Filtro De Motor | E16: 45530 | F16: 297464 | G16: 317464 | H16: 23030.17 | I16: -3030.17 | J16: 320494.17 | K16: 417 | L16: 48.15737 | M16: -54.866329 | N16: 45947 | O16: 20000 | P16: 46362.305 | Q16: Activo | T16: C000313 | U16: ACEITE 15W40 XV300 X 205LT (TAMBOR) | V16: 16 | W16: 3389.9 | X16: 54238.4 | Y16: =VLOOKUP(A16,[1]Detalle!$D$2:$CR$484,93,FALSE) -> Unilever - Unilever de Arg. S.A.
A17: BVH267 | B17: 2MC | C17: 2MC | D17: Cambio De Aceite Y Filtro De Motor | E17: 45530 | F17: 297464 | G17: 317464 | H17: 23030.17 | I17: -3030.17 | J17: 320494.17 | K17: 417 | L17: 48.15737 | M17: -54.866329 | N17: 45947 | O17: 20000 | P17: 46362.305 | Q17: Activo | T17: C002301 | U17: FILTRO DE ACEITE 6 CILINDROS MB 1318/1218/1215/914/712/1418/915/815 - MANN HU931/5X | V17: 1 | W17: 8513.28 | X17: 8513.28 | Y17: =VLOOKUP(A17,[1]Detalle!$D$2:$CR$484,93,FALSE) -> Unilever - Unilever de Arg. S.A.
A18: CVF923 | B18: 2MC | C18: 2MC | D18: Cambio De Aceite Y Filtro De Motor | E18: 45798 | F18: 32992.1 | G18: 52992.1 | H18: 9749.3 | I18: 10250.7 | J18: 42741.4 | K18: 149 | L18: 52.850396 | M18: 156.66297 | N18: 45947 | O18: 20000 | P18: 46103.663 | Q18: Activo | T18: C000313 | U18: ACEITE 15W40 XV300 X 205LT (TAMBOR) | V18: 16 | W18: 3389.9 | X18: 54238.4 | Y18: =VLOOKUP(A18,[1]Detalle!$D$2:$CR$484,93,FALSE) -> JOHNSON - SC JOHNSON DE ARGENTINA SAIC
A19: CVF923 | B19: 2MC | C19: 2MC | D19: Cambio De Aceite Y Filtro De Motor | E19: 45798 | F19: 32992.1 | G19: 52992.1 | H19: 9749.3 | I19: 10250.7 | J19: 42741.4 | K19: 149 | L19: 52.850396 | M19: 156.66297 | N19: 45947 | O19: 20000 | P19: 46103.663 | Q19: Activo | T19: C002301 | U19: FILTRO DE ACEITE 6 CILINDROS MB 1318/1218/1215/914/712/1418/915/815 - MANN HU931/5X | V19: 1 | W19: 8513.28 | X19: 8513.28 | Y19: =VLOOKUP(A19,[1]Detalle!$D$2:$CR$484,93,FALSE) -> JOHNSON - SC JOHNSON DE ARGENTINA SAIC
... A91: KGM735 | B91: 3MC | C91: 3MC | D91: Cambio De Filtro Gas Oíl Y Trampa De Agua | E91: 45898 | F91: 279340 | G91: 299340 | H91: 2584.2 | I91: 17415.8 | J91: 281924.2 | K91: 49 | L91: 86.131808 | M91: 330.22761 | N91: 45947 | O91: 20000 | P91: 46277.228 | Q91: Activo | T91: C003103 | U91: FILTRO TRAMPA DE AGUA - WIX (WF 10288) | V91: 1 | W91: 19410.24 | X91: 19410.24 | Y91: =VLOOKUP(A91,[1]Detalle!$D$2:$CR$484,93,FALSE) -> Arcor S.A.I.C.
A92: AF338VO | B92: 3MC | C92: 3MC | D92: Cambio De Filtro Gas Oíl Y Trampa De Agua | E92: - | L92: 51.093037 | N92: 45947 | O92: 20000 | P92: 46338.443 | Q92: Activo | T92: C001031 | U92: FILTRO DE COMBUSTIBLE MANN PU1046/1X | V92: 1 | W92: 10535.04 | X92: 10535.04 | Y92: =VLOOKUP(A92,[1]Detalle!$D$2:$CR$484,93,FALSE) -> CMQ_TTE - QUILMES TTE
A93: AF338VO | B93: 3MC | C93: 3MC | D93: Cambio De Filtro Gas Oíl Y Trampa De Agua | E93: - | L93: 51.093037 | N93: 45947 | O93: 20000 | P93: 46338.443 | Q93: Activo | T93: C003103 | U93: FILTRO TRAMPA DE AGUA - WIX (WF 10288) | V93: 1 | W93: 19410.24 | X93: 19410.24 | Y93: =VLOOKUP(A93,[1]Detalle!$D$2:$CR$484,93,FALSE) -> CMQ_TTE - QUILMES TTE
A94: AF364MN | B94: 3MC | C94: 3MC | D94: Cambio De Filtro Gas Oíl Y Trampa De Agua | E94: 45461 | F94: 38855.1 | G94: 58855.1 | H94: 22989.9 | I94: -2989.9 | J94: 61845 | K94: 486 | L94: 45.422519 | M94: -63.205642 | N94: 45947 | O94: 20000 | P94: 46387.31 | Q94: Activo | T94: C001031 | U94: FILTRO DE COMBUSTIBLE MANN PU1046/1X | V94: 1 | W94: 10535.04 | X94: 10535.04 | Y94: =VLOOKUP(A94,[1]Detalle!$D$2:$CR$484,93,FALSE) -> CMQ_TTE - QUILMES TTE
A95: AF364MN | B95: 3MC | C95: 3MC | D95: Cambio De Filtro Gas Oíl Y Trampa De Agua | E95: 45461 | F95: 38855.1 | G95: 58855.1 | H95: 22989.9 | I95: -2989.9 | J95: 61845 | K95: 486 | L95: 45.422519 | M95: -63.205642 | N95: 45947 | O95: 20000 | P95: 46387.31 | Q95: Activo | T95: C003103 | U95: FILTRO TRAMPA DE AGUA - WIX (WF 10288) | V95: 1 | W95: 19410.24 | X95: 19410.24 | Y95: =VLOOKUP(A95,[1]Detalle!$D$2:$CR$484,93,FALSE) -> CMQ_TTE - QUILMES TTE
A96: GDR526 | B96: 3MC | C96: 3MC | D96: Cambio De Filtro Gas Oíl Y Trampa De Agua | E96: 45882 | F96: 289935 | G96: 309935 | H96: 2579.9 | I96: 17420.1 | J96: 292514.9 | K96: 65 | L96: 56.324627 | M96: 438.8955 | N96: 45947 | O96: 20000 | P96: 46385.895 | Q96: Activo | T96: C001031 | U96: FILTRO DE COMBUSTIBLE MANN PU1046/1X | V96: 1 | W96: 10535.04 | X96: 10535.04 | Y96: =VLOOKUP(A96,[1]Detalle!$D$2:$CR$484,93,FALSE) -> Alfavinil SA
A97: GDR526 | B97: 3MC | C97: 3MC | D97: Cambio De Filtro Gas Oíl Y Trampa De Agua | E97: 45882 | F97: 289935 | G97: 309935 | H97: 2579.9 | I97: 17420.1 | J97: 292514.9 | K97: 65 | L97: 56.324627 | M97: 438.8955 | N97: 45947 | O97: 20000 | P97: 46385.895 | Q97: Activo | T97: C003103 | U97: FILTRO TRAMPA DE AGUA - WIX (WF 10288) | V97: 1 | W97: 19410.24 | X97: 19410.24 | Y97: =VLOOKUP(A97,[1]Detalle!$D$2:$CR$484,93,FALSE) -> Alfavinil SA
A98: AF518DM | B98: 3MC | C98: 3MC | D98: Cambio De Filtro Gas Oíl Y Trampa De Agua | E98: 45545 | F98: 42714.2 | G98: 62714.2 | H98: 21856.56 | I98: -1856.56 | J98: 64570.76 | K98: 402 | L98: 53.502481 | M98: -34.147053 | N98: 45947 | O98: 20000 | P98: 46320.814 | Q98: Activo | T98: C001031 | U98: FILTRO DE COMBUSTIBLE MANN PU1046/1X | V98: 1 | W98: 10535.04 | X98: 10535.04 | Y98: =VLOOKUP(A98,[1]Detalle!$D$2:$CR$484,93,FALSE) -> CMQ_TTE - QUILMES TTE
A99: AF518DM | B99: 3MC | C99: 3MC | D99: Cambio De Filtro Gas Oíl Y Trampa De Agua | E99: 45545 | F99: 42714.2 | G99: 62714.2 | H99: 21856.56 | I99: -1856.56 | J99: 64570.76 | K99: 402 | L99: 53.502481 | M99: -34.147053 | N99: 45947 | O99: 20000 | P99: 46320.814 | Q99: Activo | T99: C003103 | U99: FILTRO TRAMPA DE AGUA - WIX (WF 10288) | V99: 1 | W99: 19410.24 | X99: 19410.24 | Y99: =VLOOKUP(A99,[1]Detalle!$D$2:$CR$484,93,FALSE) -> CMQ_TTE - QUILMES TTE
A100: GEB769 | B100: 3MC | C100: 3MC | D100: Cambio De Filtro Gas Oíl Y Trampa De Agua | E100: 45546 | F100: 235609 | G100: 255609 | H100: 21825.48 | I100: -1825.48 | J100: 257434.48 | K100: 401 | L100: 61.857388 | M100: -33.539582 | N100: 45947 | O100: 20000 | P100: 46270.324 | Q100: Activo | T100: C001031 | U100: FILTRO DE COMBUSTIBLE MANN PU1046/1X | V100: 1 | W100: 10535.04 | X100: 10535.04 | Y100: =VLOOKUP(A100,[1]Detalle!$D$2:$CR$484,93,FALSE) -> Topacio
A101: GEB769 | B101: 3MC | C101: 3MC | D101: Cambio De Filtro Gas Oíl Y Trampa De Agua | E101: 45546 | F101: 235609 | G101: 255609 | H101: 21825.48 | I101: -1825.48 | J101: 257434.48 | K101: 401 | L101: 61.857388 | M101: -33.539582 | N101: 45947 | O101: 20000 | P101: 46270.324 | Q101: Activo | T101: C003103 | U101: FILTRO TRAMPA DE AGUA - WIX (WF 10288) | V101: 1 | W101: 19410.24 | X101: 19410.24 | Y101: =VLOOKUP(A101,[1]Detalle!$D$2:$CR$484,93,FALSE) -> Topacio
A102: GKK500 | B102: 3MC | C102: 3MC | D102: Cambio De Filtro Gas Oíl Y Trampa De Agua | E102: 45840 | F102: 40688 | G102: 60688 | H102: 18559.9 | I102: 1440.1 | J102: 59247.9 | K102: 107 | L102: 129.25862 | M102: 8.3023454 | N102: 45947 | O102: 20000 | P102: 46110.031 | Q102: Activo | T102: C001031 | U102: FILTRO DE COMBUSTIBLE MANN PU1046/1X | V102: 1 | W102: 10535.04 | X102: 10535.04 | Y102: =VLOOKUP(A102,[1]Detalle!$D$2:$CR$484,93,FALSE) -> SUC_MEN - Sucursal Mendoza
A103: GKK500 | B103: 3MC | C103: 3MC | D103: Cambio De Filtro Gas Oíl Y Trampa De Agua | E103: 45840 | F103: 40688 | G103: 60688 | H103: 18559.9 | I103: 1440.1 | J103: 59247.9 | K103: 107 | L103: 129.25862 | M103: 8.3023454 | N103: 45947 | O103: 20000 | P103: 46110.031 | Q103: Activo | T103: C003103 | U103: FILTRO TRAMPA DE AGUA - WIX (WF 10288) | V103: 1 | W103: 19410.24 | X103: 19410.24 | Y103: =VLOOKUP(A103,[1]Detalle!$D$2:$CR$484,93,FALSE) -> SUC_MEN - Sucursal Mendoza
A104: GLT551 | B104: 3MC | C104: 3MC | D104: Cambio De Filtro Gas Oíl Y Trampa De Agua | E104: 45745 | F104: 484970 | G104: 504970 | H104: 6360.2 | I104: 13639.8 | J104: 491330.2 | K104: 202 | L104: 30.732695 | M104: 433.20015 | N104: 45947 | O104: 20000 | P104: 46380.2 | Q104: Activo | T104: C001031 | U104: FILTRO DE COMBUSTIBLE MANN PU1046/1X | V104: 1 | W104: 10535.04 | X104: 10535.04 | Y104: =VLOOKUP(A104,[1]Detalle!$D$2:$CR$484,93,FALSE) -> CCU_MZA - Comp. Cerv. Unidas - MZA
A105: GLT551 | B105: 3MC | C105: 3MC | D105: Cambio De Filtro Gas Oíl Y Trampa De Agua | E105: 45745 | F105: 484970 | G105: 504970 | H105: 6360.2 | I105: 13639.8 | J105: 491330.2 | K105: 202 | L105: 30.732695 | M105: 433.20015 | N105: 45947 | O105: 20000 | P105: 46380.2 | Q105: Activo | T105: C003103 | U105: FILTRO TRAMPA DE AGUA - WIX (WF 10288) | V105: 1 | W105: 19410.24 | X105: 19410.24 | Y105: =VLOOKUP(A105,[1]Detalle!$D$2:$CR$484,93,FALSE) -> CCU_MZA - Comp. Cerv. Unidas - MZA
... A163: AF642OT | B163: 3MC | C163: 3MC | D163: Cambio De Filtro Gas Oíl Y Trampa De Agua | E163: 45702 | F163: 44127.9 | G163: 64127.9 | H163: 9317.4 | I163: 10682.6 | J163: 53445.3 | K163: 245 | L163: 40.395368 | M163: 280.89778 | N163: 45947 | O163: 20000 | P163: 46227.898 | Q163: Activo | T163: C003103 | U163: FILTRO TRAMPA DE AGUA - WIX (WF 10288) | V163: 1 | W163: 19410.24 | X163: 19410.24 | Y163: =VLOOKUP(A163,[1]Detalle!$D$2:$CR$484,93,FALSE) -> CCU_MZA - Comp. Cerv. Unidas - MZA
A164: AE243WV | B164: 3MC | C164: 3MC | D164: Cambio De Filtro Gas Oíl Y Trampa De Agua | E164: 45848 | F164: 697850 | G164: 717850 | H164: 28773 | I164: -8773 | J164: 726623 | K164: 99 | L164: 365 | M164: -30.185486 | N164: 45947 | O164: 20000 | P164: 46056.589 | Q164: Activo | R164: 46056.589 | S164: 46111.384 | T164: C001031 | U164: FILTRO DE COMBUSTIBLE MANN PU1046/1X | V164: 1 | W164: 10535.04 | X164: 10535.04 | Y164: =VLOOKUP(A164,[1]Detalle!$D$2:$CR$484,93,FALSE) -> CENCOMLD - Cencosud SA - Mendoza
A165: AE243WV | B165: 3MC | C165: 3MC | D165: Cambio De Filtro Gas Oíl Y Trampa De Agua | E165: 45848 | F165: 697850 | G165: 717850 | H165: 28773 | I165: -8773 | J165: 726623 | K165: 99 | L165: 365 | M165: -30.185486 | N165: 45947 | O165: 20000 | P165: 46056.589 | Q165: Activo | R165: 46056.589 | S165: 46111.384 | T165: C003103 | U165: FILTRO TRAMPA DE AGUA - WIX (WF 10288) | V165: 1 | W165: 19410.24 | X165: 19410.24 | Y165: =VLOOKUP(A165,[1]Detalle!$D$2:$CR$484,93,FALSE) -> CENCOMLD - Cencosud SA - Mendoza
A166: NIE150 | B166: 3MC | C166: 3MC | D166: Cambio De Filtro Gas Oíl Y Trampa De Agua | E166: 45763 | F166: 435565 | G166: 455565 | H166: 16726.9 | I166: 3273.1 | J166: 452291.9 | K166: 184 | L166: 76.021812 | M166: 36.004902 | N166: 45947 | O166: 20000 | P166: 46246.087 | Q166: Activo | T166: C001031 | U166: FILTRO DE COMBUSTIBLE MANN PU1046/1X | V166: 1 | W166: 10535.04 | X166: 10535.04 | Y166: =VLOOKUP(A166,[1]Detalle!$D$2:$CR$484,93,FALSE) -> Papelera - Papelera del Plata S.A.
A167: NIE150 | B167: 3MC | C167: 3MC | D167: Cambio De Filtro Gas Oíl Y Trampa De Agua | E167: 45763 | F167: 435565 | G167: 455565 | H167: 16726.9 | I167: 3273.1 | J167: 452291.9 | K167: 184 | L167: 76.021812 | M167: 36.004902 | N167: 45947 | O167: 20000 | P167: 46246.087 | Q167: Activo | T167: C003103 | U167: FILTRO TRAMPA DE AGUA - WIX (WF 10288) | V167: 1 | W167: 19410.24 | X167: 19410.24 | Y167: =VLOOKUP(A167,[1]Detalle!$D$2:$CR$484,93,FALSE) -> Papelera - Papelera del Plata S.A.
A168: GJC632 | B168: 3MC | C168: 3MC | D168: Cambio De Filtro Gas Oíl Y Trampa De Agua | E168: 45763 | F168: 255203 | G168: 275203 | H168: 12233.5 | I168: 7766.5 | J168: 267436.5 | K168: 184 | L168: 57.024097 | M168: 116.81334 | N168: 45947 | O168: 20000 | P168: 46063.813 | Q168: Activo | T168: C001031 | U168: FILTRO DE COMBUSTIBLE MANN PU1046/1X | V168: 1 | W168: 10535.04 | X168: 10535.04 | Y168: =VLOOKUP(A168,[1]Detalle!$D$2:$CR$484,93,FALSE) -> Topacio
...
